Workbook

Sheet Raw Sales Data
A1: Date | B1: Product | C1: Category | D1: Quantity | E1: Unit | F1: Cost Price | G1: Selling Price | H1: Revenue | I1: Profit | J1: Margin
A2: 01-08-2025 | B2: UltraTech | C2: Cement | D2: 10 | E2: Bag | F2: 270 | G2: 340 | H2: =D2*G2 -> 3400 | I2: =(G2 - F2) * D2 -> 700 | J2: =(G2-F2)/G2*100 -> 20.588235
A3: 01-08-2025 | B3: Nuvoco | C3: Cement | D3: 20 | E3: Bag | F3: 290 | G3: 350 | H3: =D3*G3 -> 7000 | I3: =(G3 - F3) * D3 -> 1200 | J3: =(G3-F3)/G3*100 -> 17.142857
A4: 01-08-2025 | B4: JSW | C4: Cement | D4: 5 | E4: Bag | F4: 270 | G4: 320 | H4: =D4*G4 -> 1600 | I4: =(G4 - F4) * D4 -> 250 | J4: =(G4-F4)/G4*100 -> 15.625
A5: 02-08-2025 | B5: Stirrup_Square | C5: Stirrups | D5: 100 | E5: Pcs | F5: 8 | G5: 12 | H5: =D5*G5 -> 1200 | I5: =(G5 - F5) * D5 -> 400 | J5: =(G5-F5)/G5*100 -> 33.333333
A6: 02-08-2025 | B6: Stirrup_Circular | C6: Stirrups | D6: 150 | E6: Pcs | F6: 9 | G6: 10 | H6: =D6*G6 -> 1500 | I6: =(G6 - F6) * D6 -> 150 | J6: =(G6-F6)/G6*100 -> 10
A7: 02-08-2025 | B7: Binding_Wire | C7: Wire | D7: 5 | E7: Kg | F7: 70 | G7: 76 | H7: =D7*G7 -> 380 | I7: =(G7 - F7) * D7 -> 30 | J7: =(G7-F7)/G7*100 -> 7.8947368
A8: 02-08-2025 | B8: TMT_10mm | C8: TMT_Bars | D8: 71 | E8: Kg | F8: 51 | G8: 55 | H8: =D8*G8 -> 3905 | I8: =(G8 - F8) * D8 -> 284 | J8: =(G8-F8)/G8*100 -> 7.2727273
A9: 02-08-2025 | B9: Primer | C9: Primer | D9: 5 | E9: Liters | F9: 180 | G9: 220 | H9: =D9*G9 -> 1100 | I9: =(G9 - F9) * D9 -> 200 | J9: =(G9-F9)/G9*100 -> 18.181818
A10: 02-08-2025 | B10: UltraTech | C10: Cement | D10: 50 | E10: Bag | F10: 270 | G10: 340 | H10: =D10*G10 -> 17000 | I10: =(G10 - F10) * D10 -> 3500 | J10: =(G10-F10)/G10*100 -> 20.588235
A11: 02-08-2025 | B11: Nuvoco | C11: Cement | D11: 10 | E11: Bag | F11: 290 | G11: 350 | H11: =D11*G11 -> 3500 | I11: =(G11 - F11) * D11 -> 600 | J11: =(G11-F11)/G11*100 -> 17.142857
A12: 03-08-2025 | B12: Paint | C12: Paint | D12: 2 | E12: Liters | F12: 240 | G12: 280 | H12: =D12*G12 -> 560 | I12: =(G12 - F12) * D12 -> 80 | J12: =(G12-F12)/G12*100 -> 14.285714
A13: 03-08-2025 | B13: Stirrup_Rect | C13: Stirrups | D13: 160 | E13: Pcs | F13: 8 | G13: 12 | H13: =D13*G13 -> 1920 | I13: =(G13 - F13) * D13 -> 640 | J13: =(G13-F13)/G13*100 -> 33.333333
... A35: 07-08-2025 | B35: Stirrup_Rect | C35: Stirrups | D35: 60 | E35: Pcs | F35: 8 | G35: 12 | H35: =D35*G35 -> 720 | I35: =(G35 - F35) * D35 -> 240 | J35: =(G35-F35)/G35*100 -> 33.333333
A36: 45846 | B36: Binding_Wire | C36: Wire | D36: 10 | E36: Kg | F36: 70 | G36: 76 | H36: =D36*G36 -> 760 | I36: =(G36 - F36) * D36 -> 60 | J36: =(G36-F36)/G36*100 -> 7.8947368
A37: 07-08-2025 | B37: UltraTech | C37: Cement | D37: 20 | E37: Bag | F37: 270 | G37: 340 | H37: =D37*G37 -> 6800 | I37: =(G37 - F37) * D37 -> 1400 | J37: =(G37-F37)/G37*100 -> 20.588235
A38: 08-08-2025 | B38: Paint | C38: Paint | D38: 4 | E38: Liters | F38: 240 | G38: 280 | H38: =D38*G38 -> 1120 | I38: =(G38 - F38) * D38 -> 160 | J38: =(G38-F38)/G38*100 -> 14.285714
A39: 08-08-2025 | B39: Stirrup_Circular | C39: Stirrups | D39: 25 | E39: Pcs | F39: 9 | G39: 10 | H39: =D39*G39 -> 250 | I39: =(G39 - F39) * D39 -> 25 | J39: =(G39-F39)/G39*100 -> 10
A40: 08-08-2025 | B40: JSW | C40: Cement | D40: 5 | E40: Bag | F40: 270 | G40: 320 | H40: =D40*G40 -> 1600 | I40: =(G40 - F40) * D40 -> 250 | J40: =(G40-F40)/G40*100 -> 15.625
A41: 08-08-2025 | B41: Primer | C41: Primer | D41: 2 | E41: Liters | F41: 180 | G41: 220 | H41: =D41*G41 -> 440 | I41: =(G41 - F41) * D41 -> 80 | J41: =(G41-F41)/G41*100 -> 18.181818
A42: 09-08-2025 | B42: TMT_10mm | C42: TMT_Bars | D42: 142 | E42: Kg | F42: 51 | G42: 55 | H42: =D42*G42 -> 7810 | I42: =(G42 - F42) * D42 -> 568 | J42: =(G42-F42)/G42*100 -> 7.2727273
A43: 09-08-2025 | B43: UltraTech | C43: Cement | D43: 2 | E43: Bag | F43: 270 | G43: 340 | H43: =D43*G43 -> 680 | I43: =(G43 - F43) * D43 -> 140 | J43: =(G43-F43)/G43*100 -> 20.588235
A44: 09-08-2025 | B44: Paint | C44: Paint | D44: 20 | E44: Liters | F44: 240 | G44: 280 | H44: =D44*G44 -> 5600 | I44: =(G44 - F44) * D44 -> 800 | J44: =(G44-F44)/G44*100 -> 14.285714
A45: 09-08-2025 | B45: TMT_12mm | C45: TMT_Bars | D45: 51 | E45: Kg | F45: 52 | G45: 55 | H45: =D45*G45 -> 2805 | I45: =(G45 - F45) * D45 -> 153 | J45: =(G45-F45)/G45*100 -> 5.4545455
A46: 10-08-2025 | B46: Stirrup_Rect | C46: Stirrups | D46: 100 | E46: Pcs | F46: 8 | G46: 12 | H46: =D46*G46 -> 1200 | I46: =(G46 - F46) * D46 -> 400 | J46: =(G46-F46)/G46*100 -> 33.333333
A47: 10-08-2025 | B47: Primer | C47: Primer | D47: 5 | E47: Liters | F47: 180 | G47: 220 | H47: =D47*G47 -> 1100 | I47: =(G47 - F47) * D47 -> 200 | J47: =(G47-F47)/G47*100 -> 18.181818
A48: 11-08-2025 | B48: Primer | C48: Primer | D48: 2 | E48: Liters | F48: 180 | G48: 220 | H48: =D48*G48 -> 440 | I48: =(G48 - F48) * D48 -> 80 | J48: =(G48-F48)/G48*100 -> 18.181818
... A129: 01-09-2025 | B129: UltraTech | C129: Cement | D129: 1 | E129: Bag | F129: 270 | G129: 340 | H129: =D129*G129 -> 340 | I129: =(G129 - F129) * D129 -> 70 | J129: =(G129-F129)/G129*100 -> 20.588235
A130: 45666 | B130: Tarpaulin_Cover | C130: Cover | D130: 4 | E130: Pcs | F130: 360 | G130: 400 | H130: =D130*G130 -> 1600 | I130: =(G130 - F130) * D130 -> 160 | J130: =(G130-F130)/G130*100 -> 10
A131: 02-09-2025 | B131: JSW | C131: Cement | D131: 3 | E131: Bag | F131: 270 | G131: 320 | H131: =D131*G131 -> 960 | I131: =(G131 - F131) * D131 -> 150 | J131: =(G131-F131)/G131*100 -> 15.625
A132: 02-09-2025 | B132: TMT_10mm | C132: TMT_Bars | D132: 71 | E132: Kg | F132: 51 | G132: 55 | H132: =D132*G132 -> 3905 | I132: =(G132 - F132) * D132 -> 284 | J132: =(G132-F132)/G132*100 -> 7.2727273
A133: 02-09-2025 | B133: Paint | C133: Paint | D133: 5 | E133: Liters | F133: 240 | G133: 280 | H133: =D133*G133 -> 1400 | I133: =(G133 - F133) * D133 -> 200 | J133: =(G133-F133)/G133*100 -> 14.285714
A134: 02-09-2025 | B134: TMT_12mm | C134: TMT_Bars | D134: 51 | E134: Kg | F134: 52 | G134: 55 | H134: =D134*G134 -> 2805 | I134: =(G134 - F134) * D134 -> 153 | J134: =(G134-F134)/G134*100 -> 5.4545455
A135: 03-09-2025 | B135: Nuvoco | C135: Cement | D135: 4 | E135: Bag | F135: 290 | G135: 350 | H135: =D135*G135 -> 1400 | I135: =(G135 - F135) * D135 -> 240 | J135: =(G135-F135)/G135*100 -> 17.142857
A136: 03-09-2025 | B136: JSW | C136: Cement | D136: 4 | E136: Bag | F136: 270 | G136: 320 | H136: =D136*G136 -> 1280 | I136: =(G136 - F136) * D136 -> 200 | J136: =(G136-F136)/G136*100 -> 15.625
A137: 04-09-2025 | B137: TMT_12mm | C137: TMT_Bars | D137: 51 | E137: Kg | F137: 52 | G137: 55 | H137: =D137*G137 -> 2805 | I137: =(G137 - F137) * D137 -> 153 | J137: =(G137-F137)/G137*100 -> 5.4545455
A138: 04-09-2025 | B138: Primer | C138: Primer | D138: 5 | E138: Liters | F138: 180 | G138: 220 | H138: =D138*G138 -> 1100 | I138: =(G138 - F138) * D138 -> 200 | J138: =(G138-F138)/G138*100 -> 18.181818
A139: 04-09-2025 | B139: Nuvoco | C139: Cement | D139: 12 | E139: Bag | F139: 290 | G139: 350 | H139: =D139*G139 -> 4200 | I139: =(G139 - F139) * D139 -> 720 | J139: =(G139-F139)/G139*100 -> 17.142857
A140: 04-09-2025 | B140: TMT_10mm | C140: TMT_Bars | D140: 142 | E140: Kg | F140: 51 | G140: 55 | H140: =D140*G140 -> 7810 | I140: =(G140 - F140) * D140 -> 568 | J140: =(G140-F140)/G140*100 -> 7.2727273
A141: 04-09-2025 | B141: Stirrup_Circular | C141: Stirrups | D141: 200 | E141: Pcs | F141: 9 | G141: 10 | H141: =D141*G141 -> 2000 | I141: =(G141 - F141) * D141 -> 200 | J141: =(G141-F141)/G141*100 -> 10
...

Sheet Cleaned Data
C1: Cement(Bags) | H1: TMT Bars(kg) | K1: Stirrups(Pcs) | N1: Paint(Litres) | O1: Primer(Liters) | P1: Wire(Kg) | Q1: Cover(Pcs)
A2: Date | B2: Month | C2: Nuvoco | D2: Nuvoco_Z | E2: UltraTech | F2: JSW | G2: Concreto | H2: TMT_8mm | I2: TMT_10mm | J2: TMT_12mm | K2: Stirrup_Square | L2: Stirrup_Circular | M2: Stirrup_Rect | N2: Paint | O2: Primer | P2: Binding_Wire | Q2: Tarpaulin_Cover | R2: Daily Total
A3: 01-08-2025 | B3: Aug 2025 | C3: 20 | D3: =STANDARDIZE(C3, 6.15, 15.41) -> 0.89876703 | E3: 10 | F3: 5 | G3: 0 | H3: 0 | I3: 0 | J3: 0 | K3: 0 | L3: 0 | M3: 0 | N3: 0 | O3: 0 | P3: 0 | Q3: 0 | R3: 35
A4: 02-08-2025 | B4: Aug 2025 | C4: 10 | D4: =STANDARDIZE(C4, 6.15, 15.41) -> 0.24983777 | E4: 50 | F4: 0 | G4: 0 | H4: 0 | I4: 71 | J4: 0 | K4: 100 | L4: 150 | M4: 0 | N4: 0 | O4: 5 | P4: 5 | Q4: 0 | R4: 391
A5: 03-08-2025 | B5: Aug 2025 | C5: 0 | D5: =STANDARDIZE(C5, 6.15, 15.41) -> -0.3990915 | E5: 0 | F5: 20 | G5: 0 | H5: 0 | I5: 0 | J5: 0 | K5: 200 | L5: 0 | M5: 320 | N5: 2 | O5: 0 | P5: 0 | Q5: 0 | R5: 542
A6: 04-08-2025 | B6: Aug 2025 | C6: 30 | D6: =STANDARDIZE(C6, 6.15, 15.41) -> 1.5476963 | E6: 15 | F6: 5 | G6: 0 | H6: 0 | I6: 0 | J6: 102 | K6: 0 | L6: 0 | M6: 0 | N6: 5 | O6: 10 | P6: 0 | Q6: 0 | R6: 167
A7: 05-08-2025 | B7: Aug 2025 | C7: 0 | D7: =STANDARDIZE(C7, 6.15, 15.41) -> -0.3990915 | E7: 0 | F7: 1 | G7: 0 | H7: 0 | I7: 142 | J7: 51 | K7: 50 | L7: 0 | M7: 0 | N7: 5 | O7: 0 | P7: 0 | Q7: 0 | R7: 249
A8: 06-08-2025 | B8: Aug 2025 | C8: 0 | D8: =STANDARDIZE(C8, 6.15, 15.41) -> -0.3990915 | E8: 10 | F8: 0 | G8: 0 | H8: 0 | I8: 0 | J8: 0 | K8: 50 | L8: 0 | M8: 0 | N8: 0 | O8: 2 | P8: 0 | Q8: 0 | R8: 62
A9: 07-08-2025 | B9: Aug 2025 | C9: 0 | D9: =STANDARDIZE(C9, 6.15, 15.41) -> -0.3990915 | E9: 20 | F9: 0 | G9: 0 | H9: 0 | I9: 0 | J9: 0 | K9: 150 | L9: 125 | M9: 60 | N9: 0 | O9: 0 | P9: 10 | Q9: 0 | R9: 365
A10: 08-08-2025 | B10: Aug 2025 | C10: 0 | D10: =STANDARDIZE(C10, 6.15, 15.41) -> -0.3990915 | E10: 0 | F10: 5 | G10: 0 | H10: 0 | I10: 0 | J10: 0 | K10: 0 | L10: 25 | M10: 0 | N10: 4 | O10: 2 | P10: 0 | Q10: 0 | R10: 36
A11: 09-08-2025 | B11: Aug 2025 | C11: 0 | D11: =STANDARDIZE(C11, 6.15, 15.41) -> -0.3990915 | E11: 2 | F11: 0 | G11: 0 | H11: 0 | I11: 142 | J11: 51 | K11: 0 | L11: 0 | M11: 0 | N11: 20 | O11: 0 | P11: 0 | Q11: 0 | R11: 215
A12: 10-08-2025 | B12: Aug 2025 | C12: 0 | D12: =STANDARDIZE(C12, 6.15, 15.41) -> -0.3990915 | E12: 0 | F12: 0 | G12: 0 | H12: 0 | I12: 0 | J12: 0 | K12: 0 | L12: 0 | M12: 100 | N12: 0 | O12: 5 | P12: 0 | Q12: 0 | R12: 105
A13: 11-08-2025 | B13: Aug 2025 | C13: 0 | D13: =STANDARDIZE(C13, 6.15, 15.41) -> -0.3990915 | E13: 0 | F13: 15 | G13: 4 | H13: 0 | I13: 0 | J13: 0 | K13: 0 | L13: 0 | M13: 25 | N13: 0 | O13: 2 | P13: 0 | Q13: 0 | R13: 46
A14: 12-08-2025 | B14: Aug 2025 | C14: 0 | D14: =STANDARDIZE(C14, 6.15, 15.41) -> -0.3990915 | E14: 0 | F14: 0 | G14: 0 | H14: 0 | I14: 0 | J14: 0 | K14: 140 | L14: 0 | M14: 80 | N14: 0 | O14: 0 | P14: 0 | Q14: 2 | R14: 222
... A186: 31-01-2026 | B186: Jan 2026 | C186: 0 | D186: =STANDARDIZE(C186, 6.15, 15.41) -> -0.3990915 | E186: 0 | F186: 0 | G186: 25 | H186: 0 | I186: 0 | J186: 102 | K186: 0 | L186: 0 | M186: 100 | N186: 0 | O186: 0 | P186: 0 | Q186: 0 | R186: 227
B187: skewness | C187: =skew(C3:C186) -> 3.9844358 | E187: =skew(E3:E186) -> 3.8999845 | F187: =skew(F3:F186) -> 3.8825571 | G187: =skew(G3:G186) -> 4.5722894 | H187: =skew(H3:H186) -> 4.8316354 | I187: =skew(I3:I186) -> 2.2054839 | J187: =skew(J3:J186) -> 3.8095749 | K187: =skew(K3:K186) -> 2.339173 | L187: =skew(L3:L186) -> 2.6148661 | ... Q187: =skew(Q3:Q186) -> 4.6885331 | R187: =SUM(R3:R186) -> 40861
B188: mean | C188: =AVERAGE(C3:C186) -> 6.1467391 | E188: =AVERAGE(E3:E186) -> 5.8206522 | F188: =AVERAGE(F3:F186) -> 6.2065217 | G188: =AVERAGE(G3:G186) -> 1.8369565 | H188: =AVERAGE(H3:H186) -> 3 | I188: =AVERAGE(I3:I186) -> 35.163043 | J188: =AVERAGE(J3:J186) -> 42.396739 | K188: =AVERAGE(K3:K186) -> 28.478261 | L188: =AVERAGE(L3:L186) -> 36.027174 | ... Q188: =AVERAGE(Q3:Q186) -> 0.25543478
B189: P95 | C189: =PERCENTILE(C3:C186, 0.95) -> 38.5 | E189: =PERCENTILE(E3:E186, 0.95) -> 30 | F189: =PERCENTILE(F3:F186, 0.95) -> 30 | G189: =PERCENTILE(G3:G186, 0.95) -> 18.8 | H189: =PERCENTILE(H3:H186, 0.95) -> 39.1 | I189: =PERCENTILE(I3:I186, 0.95) -> 143 | J189: =PERCENTILE(J3:J186, 0.95) -> 153 | K189: =PERCENTILE(K3:K186, 0.95) -> 158.5 | L189: =PERCENTILE(L3:L186, 0.95) -> 200 | ... Q189: =PERCENTILE(Q3:Q186, 0.95) -> 2
B190: P90 | C190: =PERCENTILE(C3:C186,0.9) -> 15.7 | E190: =PERCENTILE(E3:E186,0.9) -> 17.1 | F190: =PERCENTILE(F3:F186,0.9) -> 17.1 | G190: =IFERROR(__xludf.DUMMYFUNCTION("PERCENTILE(filter(G3:G186,G3:G186>0),0.9)"),32.999999999999986) -> 33 | H190: =IFERROR(__xludf.DUMMYFUNCTION("PERCENTILE(FILTER(H3:H186, H3:H186>0), 0.9)"),92.0) -> 92 | I190: =PERCENTILE(I3:I186,0.9) -> 142 | J190: =PERCENTILE(J3:J186,0.9) -> 102 | K190: =PERCENTILE(K3:K186,0.9) -> 127 | L190: =PERCENTILE(L3:L186,0.9) -> 150 | M190: =PERCENTILE(M3:M186,0.9) -> 200 | N190: =PERCENTILE(N3:N186,0.9) -> 10 | O190: =PERCENTILE(O3:O186,0.9) -> 10 | P190: =IFERROR(__xludf.DUMMYFUNCTION("PERCENTILE(filter(P3:P186,P3:P186>0),0.9)"),10.0) -> 10 | Q190: =IFERROR(__xludf.DUMMYFUNCTION("PERCENTILE(filter(Q3:Q186,Q3:Q186>0),0.9)"),5.0) -> 5
B191: safety stock 90 | C191: =C190-C188 -> 9.5532609 | E191: =E190-E188 -> 11.279348 | F191: =F190-F188 -> 10.893478 | G191: =G190-G188 -> 31.163043 | H191: =H190-H188 -> 89 | I191: =I190-I188 -> 106.83696 | J191: =J190-J188 -> 59.603261 | K191: =K190-K188 -> 98.521739 | L191: =L190-L188 -> 113.97283 | ... Q191: =Q190-Q188 -> 4.7445652
B192: safety stock 95 | C192: =C189-C188 -> 32.353261 | E192: =E189-E188 -> 24.179348 | F192: =F189-F188 -> 23.793478 | G192: =G189-G188 -> 16.963043 | H192: =H189-H188 -> 36.1 | I192: =I189-I188 -> 107.83696 | J192: =J189-J188 -> 110.60326 | K192: =K189-K188 -> 130.02174 | L192: =L189-L188 -> 163.97283 | ... Q192: =Q189-Q188 -> 1.7445652
B193: avg usage | C193: =C188*5 -> 30.733696 | E193: =E188*5 -> 29.103261 | F193: =F188*5 -> 31.032609 | G193: =G188*5 -> 9.1847826 | H193: =H188*5 -> 15 | I193: =I188*5 -> 175.81522 | J193: =J188*5 -> 211.9837 | K193: =K188*5 -> 142.3913 | L193: =L188*5 -> 180.13587 | ... Q193: =Q188*5 -> 1.2771739
B194: ROP 90 Percent | C194: =C191+C193 -> 40.286957 | E194: =E191+E193 -> 40.382609 | F194: =F191+F193 -> 41.926087 | G194: =G191+G193 -> 40.347826 | H194: =H191+H193 -> 104 | I194: =I191+I193 -> 282.65217 | J194: =J191+J193 -> 271.58696 | K194: =K191+K193 -> 240.91304 | L194: =L191+L193 -> 294.1087 | ... Q194: =Q191+Q193 -> 6.0217391
B195: ROP 95 Percent | C195: =C192+C193 -> 63.086957 | E195: =E192+E193 -> 53.282609 | F195: =F192+F193 -> 54.826087 | G195: =G192+G193 -> 26.147826 | H195: =H192+H193 -> 51.1 | I195: =I192+I193 -> 283.65217 | J195: =J192+J193 -> 322.58696 | K195: =K192+K193 -> 272.41304 | L195: =L192+L193 -> 344.1087 | ... Q195: =Q192+Q193 -> 3.0217391
B200: safety 90 | C200: =C190 - C188 -> 9.5532609
B261: std dev | C261: =STDEV(C74:C256) -> 17.439273 | E261: =STDEV(E74:E256) -> 18.902361 | F261: =STDEV(F74:F256) -> 19.114863 | G261: =STDEV(G74:G256) -> 8.8774539 | H261: =STDEV(H74:H256) -> 21.50774 | I261: =STDEV(I74:I256) -> 66.797329 | J261: =STDEV(J74:J256) -> 78.591553 | K261: =STDEV(K74:K256) -> 68.459989 | L261: =STDEV(L74:L256) -> 91.616535 | ... Q261: =STDEV(Q74:Q256) -> 1.458401
B262: MIN | C262: =min(C60:C243) -> 0 | E262: =min(E60:E243) -> 0 | F262: =min(F60:F243) -> 0 | G262: =min(G60:G243) -> 0
B263: Q1(25%) | C263: =percentile(C60:C243,0.25) -> 0 | E263: =percentile(E60:E243,0.25) -> 0 | F263: =percentile(F60:F243,0.25) -> 0 | G263: =percentile(G60:G243,0.25) -> 0
B264: Median | C264: =median(C60:C243) -> 0 | E264: =median(E60:E243) -> 0 | F264: =median(F60:F243) -> 0 | G264: =median(G60:G243) -> 0
B265: Q3(75%) | C265: =PERCENTILE(C60:C243,0.75) -> 6.1467391 | E265: =PERCENTILE(E60:E243,0.75) -> 6.3654891 | F265: =PERCENTILE(F60:F243,0.75) -> 5.25 | G265: =PERCENTILE(G60:G243,0.75) -> 0
B266: MAX | C266: =max(C60:C243) -> 100 | E266: =max(E60:E243) -> 100 | F266: =max(F60:F243) -> 100 | G266: =max(G60:G243) -> 50

Sheet Inventory Data
C1: Cement(Bags) | K1: TMT Bars(Kg) | Q1: Stirrups(Pieces) | W1: Paint(Liters) | Y1: Primer(Liters) | AA1: Wire(Kg) | AC1: Cover(Pieces)
C2: Nuvoco | E2: JSW | G2: UltraTech | I2: Concreto | K2: TMT 8mm | M2: TMT 10mm | O2: TMT 12mm | Q2: Stirrup(Square) | S2: Stirrup(Circular) | U2: Stirrup(Rectangle) | W2: Paints | Y2: Primers | AA2: Binding Wire | AC2: Tarpaulin Cover
A3: Weeks | B3: Weeks | C3: Opening | D3: Closing | E3: Opening | F3: Closing | G3: Opening | H3: Closing | I3: Opening | J3: Closing | K3: Opening | L3: Closing | M3: Opening | N3: Closing | O3: Opening | P3: Closing | Q3: Opening | R3: Closing | S3: Opening | T3: Closing | U3: Opening | V3: Closing | W3: Opening | X3: Closing | Y3: Opening | Z3: Closing | AA3: Opening | AB3: Closing | AC3: Opening | AD3: Closing
A4: 01-08-2025 / 07-08-2025 | B4: WEEK1 | C4: 215 | D4: 155 | E4: 80 | F4: 55 | G4: 150 | H4: 55 | I4: 85 | J4: 85 | K4: 230 | L4: 230 | M4: 426 | N4: 213 | O4: 408 | P4: 255 | Q4: 600 | R4: 50 | S4: 400 | T4: 275 | U4: 600 | V4: 220 | W4: 70 | X4: 58 | Y4: 20 | Z4: 3 | AA4: 40 | AB4: 25 | AC4: 8 | AD4: 8
A5: 08-08-2025 / 14-08-2025 | B5: WEEK2 | C5: 155 | D5: 55 | E5: 55 | F5: 12 | G5: 255 | H5: 253 | I5: 85 | J5: 81 | K5: 230 | L5: 230 | M5: 213 | N5: 0 | O5: 510 | P5: 357 | Q5: 550 | R5: 260 | S5: 275 | T5: 250 | U5: 770 | V5: 315 | W5: 58 | X5: 34 | Y5: 53 | Z5: 36 | AA5: 25 | AB5: 25 | AC5: 8 | AD5: 6
A6: 15-08-2025 / 21-08-2025 | B6: WEEK3 | C6: 255 | D6: 240 | E6: 112 | F6: 111 | G6: 253 | H6: 240 | I6: 81 | J6: 51 | K6: 230 | L6: 230 | M6: 355 | N6: -142 | O6: 357 | P6: 102 | Q6: 260 | R6: 185 | S6: 250 | T6: 180 | U6: 315 | V6: 30 | W6: 34 | X6: 34 | Y6: 36 | Z6: 27 | AA6: 25 | AB6: 15 | AC6: 6 | AD6: 6
A7: 22-08-2025 / 28-08-2025 | B7: WEEK4 | C7: 240 | D7: 234 | E7: 111 | F7: 86 | G7: 240 | H7: 240 | I7: 51 | J7: 51 | K7: 230 | L7: 230 | M7: 355 | N7: 71 | O7: 306 | P7: =306-102 -> 204 | Q7: 485 | R7: 90 | S7: 380 | T7: 130 | U7: 530 | V7: 515 | W7: 34 | X7: 34 | Y7: 27 | Z7: 23 | AA7: 15 | AB7: 10 | AC7: 6 | AD7: 3
A8: 29-08-2025 / 04-09-2025 | B8: WEEK5 | C8: 234 | D8: =234-22 -> 212 | E8: 86 | F8: 73 | G8: 240 | H8: 237 | I8: 151 | J8: 151 | K8: 230 | L8: 230 | M8: 426 | N8: 142 | O8: 306 | P8: 0 | Q8: 390 | R8: 390 | S8: 430 | T8: =430-220 -> 210 | U8: 515 | V8: =515-150 -> 365 | W8: 34 | X8: =34-16 -> 18 | Y8: 27 | Z8: 4 | AA8: 10 | AB8: 10 | AC8: 6 | AD8: 2
A9: 05-09-2025 / 11-09-2025 | B9: WEEK6 | C9: 212 | D9: 204 | E9: 173 | F9: 98 | G9: 237 | H9: 220 | I9: 151 | J9: 151 | K9: 230 | L9: 230 | M9: 497 | N9: 284 | O9: 408 | P9: 51 | Q9: 390 | R9: 295 | S9: 410 | T9: 300 | U9: 365 | V9: 200 | W9: 58 | X9: 28 | Y9: 44 | Z9: 29 | AA9: 30 | AB9: 5 | AC9: 7 | AD9: 3
A10: 12-09-2025 / 18-09-2025 | B10: WEEK7 | C10: 204 | D10: 196 | E10: 198 | F10: 153 | G10: 237 | H10: 227 | I10: 151 | J10: 119 | K10: 230 | L10: 230 | M10: 426 | N10: 71 | O10: 357 | P10: 0 | Q10: 495 | R10: 90 | S10: 300 | T10: 60 | U10: 200 | V10: 55 | W10: 28 | X10: 13 | Y10: 29 | Z10: 22 | AA10: 5 | AB10: 5 | AC10: 3 | AD10: 3
A11: 19-09-2025 / 25-09-2025 | B11: WEEK8 | C11: 196 | D11: 123 | E11: 153 | F11: 89 | G11: 227 | H11: 195 | I11: 119 | J11: 115 | K11: 230 | L11: 184 | M11: 497 | N11: 284 | O11: 306 | P11: 0 | Q11: 590 | R11: 240 | S11: 560 | T11: 230 | U11: 555 | V11: 450 | W11: 53 | X11: 27 | Y11: 62 | Z11: 30 | AA11: 25 | AB11: 25 | AC11: 8 | AD11: 6
A12: 26-09-2025 / 02-10-2025 | B12: WEEK9 | C12: 223 | D12: 223 | E12: 189 | F12: 189 | G12: 195 | H12: 192 | I12: 119 | J12: 99 | K12: 184 | L12: 184 | M12: 568 | N12: =568-284 -> 284 | O12: 510 | P12: 51 | Q12: 540 | R12: =540-150 -> 390 | S12: 530 | T12: 482 | U12: 450 | V12: 160 | W12: 27 | X12: 22 | Y12: 30 | Z12: 16 | AA12: 45 | AB12: 20 | AC12: 6 | AD12: 6
A13: 03-10-2025 / 09-10-2025 | B13: WEEK10 | C13: 223 | D13: 202 | E13: 189 | F13: 150 | G13: 192 | H13: 162 | I13: 99 | J13: 49 | K13: 184 | L13: 138 | M13: 426 | N13: -142 | O13: 1020 | P13: 204 | Q13: 390 | R13: 310 | S13: 482 | T13: 52 | U13: 1160 | V13: 310 | W13: 62 | X13: 62 | Y13: 56 | Z13: 20 | AA13: 40 | AB13: 40 | AC13: 6 | AD13: 1
A14: 10-10-2025 / 16-10-2025 | B14: WEEK11 | C14: 202 | D14: 150 | E14: 150 | F14: 31 | G14: 162 | H14: 137 | I14: 249 | J14: 224 | K14: 138 | L14: 138 | M14: 355 | N14: 355 | O14: 714 | P14: 459 | Q14: 310 | R14: 140 | S14: 352 | T14: 287 | U14: 310 | V14: -330 | W14: 62 | X14: 27 | Y14: 60 | Z14: 13 | AA14: 40 | AB14: 35 | AC14: 6 | AD14: 6
A15: 16-10-2025 / 22-10-2025 | B15: WEEK12 | C15: 150 | D15: 146 | E15: 231 | F15: 226 | G15: 137 | H15: 106 | I15: 224 | J15: 224 | K15: 138 | L15: 138 | M15: 355 | N15: 142 | O15: 459 | P15: 408 | Q15: 740 | R15: 500 | S15: 887 | T15: 840 | U15: 270 | V15: 60 | W15: 67 | X15: 17 | Y15: 53 | Z15: 46 | AA15: 35 | AB15: 35 | AC15: 6 | AD15: 4
A16: 23-10-2025 / 29-10-2025 | B16: WEEK13 | C16: 146 | D16: 141 | E16: 226 | F16: 183 | G16: 106 | H16: 106 | I16: 224 | J16: 222 | K16: 138 | L16: 138 | M16: 497 | N16: 497 | O16: 408 | P16: 255 | Q16: 500 | R16: 500 | S16: 843 | T16: 799 | U16: 560 | V16: 217 | W16: 57 | X16: 40 | Y16: 46 | Z16: 46 | AA16: 35 | AB16: 35 | AC16: 4 | AD16: 4
A17: 30-10-2025 / 05-11-2025 | B17: WEEK14 | C17: 141 | D17: 103 | E17: 183 | F17: 159 | G17: 106 | H17: 82 | I17: 222 | J17: 222 | K17: 138 | L17: 92 | M17: 497 | N17: 284 | O17: 510 | P17: 510 | Q17: 500 | R17: 175 | S17: 799 | T17: 729 | U17: 217 | V17: 27 | W17: 40 | X17: 8 | Y17: 46 | Z17: 9 | AA17: 35 | AB17: 30 | AC17: 4 | AD17: 4
A18: 06-11-2025 / 12-11-2025 | B18: WEEK15 | C18: 103 | D18: 65 | E18: 159 | F18: 141 | G18: 82 | H18: 22 | I18: 222 | J18: 189 | K18: 92 | L18: 46 | M18: 284 | N18: 142 | O18: 510 | P18: 204 | Q18: 675 | R18: 455 | S18: 729 | T18: 239 | U18: 1027 | V18: 383 | W18: 88 | X18: 36 | Y18: 49 | Z18: 23 | AA18: 30 | AB18: 30 | AC18: 14 | AD18: 14
A19: 13-11-2025 / 19-11-2025 | B19: WEEK16 | C19: 265 | D19: 130 | E19: 141 | F19: 81 | G19: 222 | H19: 112 | I19: 189 | J19: 189 | K19: 230 | L19: 138 | M19: 639 | N19: 284 | O19: 714 | P19: 459 | Q19: 455 | R19: -15 | S19: 239 | T19: 214 | U19: 983 | V19: -97 | W19: 76 | X19: 26 | Y19: 63 | Z19: 35 | AA19: 30 | AB19: 30 | AC19: 14 | AD19: 9
A20: 20-11-2025 / 26-11-2025 | B20: WEEK17 | C20: 130 | D20: 111 | E20: 281 | F20: 265 | G20: 112 | H20: 68 | I20: 189 | J20: 189 | K20: 138 | L20: 92 | M20: 639 | N20: 0 | O20: 459 | P20: 408 | Q20: 585 | R20: 210 | S20: 814 | T20: 614 | U20: 503 | V20: 453 | W20: 66 | X20: 33 | Y20: 75 | Z20: 20 | AA20: 30 | AB20: 30 | AC20: 9 | AD20: 4
A21: 27-11-2025 / 03-12-2025 | B21: WEEK18 | C21: 111 | D21: 47 | E21: 265 | F21: 225 | G21: 268 | H21: 256 | I21: 189 | J21: 186 | K21: 276 | L21: 230 | M21: 639 | N21: 497 | O21: 408 | P21: 51 | Q21: 810 | R21: 540 | S21: 614 | T21: 559 | U21: 853 | V21: 353 | W21: 73 | X21: 45 | Y21: 60 | Z21: 60 | AA21: 30 | AB21: 30 | AC21: 9 | AD21: 9
A22: 04-12-2025 / 10-12-2025 | B22: WEEK19 | C22: 247 | D22: 230 | E22: 225 | F22: 222 | G22: 256 | H22: 164 | I22: 186 | J22: 186 | K22: 230 | L22: 184 | M22: 497 | N22: 71 | O22: 561 | P22: 306 | Q22: 540 | R22: 420 | S22: 559 | T22: 9 | U22: 353 | V22: 143 | W22: 85 | X22: 40 | Y22: 60 | Z22: 21 | AA22: 30 | AB22: 30 | AC22: 9 | AD22: 9
A23: 11-12-2025 / 17-12-2025 | B23: WEEK20 | C23: 230 | D23: 162 | E23: 222 | F23: 222 | G23: 164 | H23: 57 | I23: 186 | J23: 182 | K23: 184 | L23: 184 | M23: 568 | N23: 355 | O23: 612 | P23: 153 | Q23: 420 | R23: 420 | S23: 609 | T23: -41 | U23: 743 | V23: 598 | W23: 80 | X23: 55 | Y23: 61 | Z23: 36 | AA23: 30 | AB23: 30 | AC23: 9 | AD23: 5
A24: 18-12-2025 / 24-12-2025 | B24: WEEK21 | C24: 162 | D24: 145 | E24: 222 | F24: 126 | G24: 157 | H24: 123 | I24: 182 | J24: 180 | K24: 184 | L24: 184 | M24: 852 | N24: 852 | O24: 459 | P24: 255 | Q24: 420 | R24: 300 | S24: 559 | T24: 189 | U24: 598 | V24: 98 | W24: 95 | X24: 25 | Y24: 76 | Z24: 44 | AA24: 30 | AB24: 30 | AC24: 5 | AD24: 5
... A29: 24-01-2026 / 31-01-2026 | B29: WEEK26 | C29: 113 | D29: 83 | E29: 137 | F29: 67 | G29: 174 | H29: 112 | I29: 121 | J29: 56 | K29: 230 | L29: 230 | M29: 497 | N29: 355 | O29: 563 | P29: 308 | Q29: 550 | R29: 300 | S29: 549 | T29: 349 | U29: 668 | V29: 568 | W29: 56 | X29: 36 | Y29: 63 | Z29: 11 | AA29: 35 | AB29: 25 | AC29: 8 | AD29: 3

Sheet Purchase Data
B1: Cements | F1: TMT_Bars | I1: Stirrups | L1: Paint | M1: Primer | N1: Wire | O1: Cover
A2: Weeks | B2: Nuvoco | C2: JSW | D2: UltraTech | E2: Concreto | F2: TMT 8mm | G2: TMT 10mm | H2: TMT 12mm | I2: Stirrup(Square) | J2: Stirrup(Rectangle) | K2: Stirrup(Circular) | L2: Paint | M2: Primer | N2: Binding Wire | O2: Tarpaulin Cover
A3: 01-08-2025 / 07-08-2025 | B3: 0 | C3: 0 | D3: 200 | E3: 0 | F3: 0 | G3: 0 | H3: 255 | I3: 500 | J3: 500 | K3: 0 | L3: 0 | M3: 50 | N3: 0 | O3: 0
A4: 08-08-2025 / 14-08-2025 | B4: 200 | C4: 100 | D4: 0 | E4: 0 | F4: 0 | G4: 355 | H4: 0 | I4: 0 | J4: 0 | K4: 0 | L4: 0 | M4: 0 | N4: 0 | O4: 0
A5: 15-08-2025 / 21-08-2025 | B5: 0 | C5: 0 | D5: 0 | E5: 0 | F5: 0 | G5: 497 | H5: 204 | I5: 300 | J5: 500 | K5: 200 | L5: 0 | M5: 0 | N5: 0 | O5: 0
A6: 22-08-2025 / 28-08-2025 | B6: 0 | C6: 0 | D6: 0 | E6: 100 | F6: 0 | G6: 355 | H6: 102 | I6: 300 | J6: 0 | K6: 300 | L6: 0 | M6: 0 | N6: 0 | O6: 3
A7: 29-08-2025 / 04-09-2025 | B7: 0 | C7: 100 | D7: 0 | E7: 0 | F7: 0 | G7: 355 | H7: 408 | I7: 0 | J7: 0 | K7: 200 | L7: 40 | M7: 40 | N7: 20 | O7: 5
A8: 05-09-2025 / 11-09-2025 | B8: 0 | C8: 100 | D8: 0 | E8: 0 | F8: 0 | G8: 142 | H8: 306 | I8: 200 | K8: 0 | L8: 0 | M8: 0 | N8: 0 | O8: 0
A9: 12-09-2025 / 18-09-2025 | B9: 0 | C9: 0 | D9: 0 | E9: 0 | F9: 0 | G9: 426 | H9: 306 | I9: 500 | J9: 500 | K9: 500 | L9: 40 | M9: 40 | N9: 20 | O9: 5
A10: 19-09-2025 / 25-09-2025 | B10: 100 | C10: 100 | D10: 0 | E10: 0 | F10: 0 | G10: 284 | H10: 510 | I10: 300 | J10: 0 | K10: 300 | L10: 0 | M10: 0 | N10: 20 | O10: 0
A11: 26-09-2025 / 02-10-2025 | B11: 0 | C11: 0 | D11: 0 | E11: 0 | F11: 0 | G11: 142 | H11: 969 | I11: 0 | J11: 1000 | K11: 0 | L11: 40 | M11: 40 | N11: 20 | O11: 0
A12: 03-10-2025 / 09-10-2025 | B12: 0 | C12: 0 | D12: 0 | E12: 200 | F12: 0 | G12: 497 | H12: 510 | I12: 0 | J12: 0 | K12: 300 | L12: 0 | M12: 40 | N12: 0 | O12: 5
A13: 10-10-2025 / 16-10-2025 | B13: 0 | C13: 200 | D13: 0 | E13: 0 | F13: 0 | G13: 0 | H13: 0 | I13: 600 | J13: 600 | K13: 600 | L13: 40 | M13: 40 | N13: 0 | O13: 0
A14: 16-10-2025 / 22-10-2025 | B14: 0 | C14: 0 | D14: 0 | E14: 0 | F14: 0 | G14: 355 | H14: 0 | I14: 0 | J14: 500 | K14: 0 | L14: 40 | M14: 0 | N14: 0 | O14: 0
A15: 23-10-2025 / 29-10-2025 | B15: 0 | C15: 0 | D15: 0 | E15: 0 | F15: 0 | G15: 0 | H15: 255 | I15: 0 | J15: 0 | K15: 0 | L15: 0 | M15: 0 | N15: 0 | O15: 0
A16: 30-10-2025 / 05-11-2025 | B16: 0 | C16: 0 | D16: 0 | E16: 0 | F16: 0 | G16: 0 | H16: 0 | I16: 500 | J16: 1000 | K16: 0 | L16: 80 | M16: 40 | N16: 0 | O16: 10
A17: 06-11-2025 / 12-11-2025 | B17: 200 | C17: 0 | D17: 200 | E17: 0 | F17: 184 | G17: 497 | H17: 510 | I17: 0 | J17: 600 | K17: 0 | L17: 40 | M17: 40 | N17: 0 | O17: 0
A18: 13-11-2025 / 19-11-2025 | B18: 0 | C18: 200 | D18: 0 | E18: 0 | F18: 0 | G18: 355 | H18: 0 | I18: 600 | J18: 600 | K18: 600 | L18: 40 | M18: 40 | N18: 0 | O18: 0
A19: 20-11-2025 / 26-11-2025 | B19: 0 | C19: 0 | D19: 200 | E19: 0 | F19: 184 | G19: 639 | H19: 0 | I19: 600 | J19: 400 | K19: 0 | L19: 40 | M19: 40 | N19: 0 | O19: 5
A20: 27-11-2025 / 03-12-2025 | B20: 200 | C20: 0 | D20: 0 | E20: 0 | F20: 0 | G20: 0 | H20: 510 | I20: 0 | J20: 0 | K20: 0 | L20: 40 | M20: 0 | N20: 0 | O20: 0
... A28: 24-01-2026 / 31-01-2026 | B28: 100 | C28: 100 | D28: 0 | E28: 100 | F28: 0 | G28: 0 | H28: 0 | I28: 0 | J28: 0 | K28: 0 | L28: 40 | M28: 40 | N28: 0 | O28: 10

Sheet Calculations
A4: Product | B4: Mean | C4: Median | D4: Mode | E4: Column 11 | F4: Standard Deviation | G4: Min | H4: Column 12 | I4: Max | J4: Range | K4: Column 13 | L4: Sum | M4: Count (Sale Days) | O4: Month | P4: Revenue | Q4: Profit | S4: Month | T4: Revenue | U4: Profit
A5: Nuvoco | B5: 6.15 | C5: 5 | D5: 2 | F5: 15.41 | G5: 1 | I5: 100 | J5: 100 | L5: 1131 | M5: 74 | O5: August | P5: 337786 | Q5: 49794 | S5: August | T5: 337786 | U5: 49794
A6: UltraTech | B6: 5.82 | C6: 10 | D6: 2 | F6: 15.55 | G6: 1 | I6: 100 | J6: 100 | L6: 1071 | M6: 56 | O6: September | P6: 372451 | Q6: 45863 | S6: September | T6: 372451 | U6: 45863
A7: JSW | B7: 6.21 | C7: 8 | D7: 1 | F7: 15.65 | G7: 1 | I7: 100 | J7: 100 | L7: 1142 | M7: 73 | O7: October | P7: 369845 | Q7: 50566 | S7: October | T7: 369845 | U7: 50566 | W7: Product | X7: Unit | Y7: Data Type | Z7: Mean | AA7: Standard Deviation | AB7: Min | AC7: Max | AD7: Count (Sale Days) | AE7: Skewness
A8: Concreto | B8: 1.84 | C8: 16 | D8: 4 | F8: 7.15 | G8: 2 | I8: 50 | J8: 50 | L8: 338 | M8: 19 | O8: November | P8: 518682 | Q8: 77245 | S8: November | T8: 518682 | U8: 77245 | W8: Nuvoco | X8: Kg | Y8: Discrete | Z8: 6.15 | AA8: 15.41 | AB8: 1 | AC8: 100 | AD8: 74 | AE8: 3.98
A9: TMT_8mm | B9: 3 | C9: 46 | D9: 46 | F9: 13.26 | G9: 46 | I9: 92 | J9: 92 | L9: 552 | M9: 10 | O9: December | P9: 426072 | Q9: 57994 | S9: December | T9: 426072 | U9: 57994 | W9: UltraTech | X9: Kg | Y9: Discrete | Z9: 5.82 | AA9: 15.55 | AB9: 1 | AC9: 100 | AD9: 56 | AE9: 3.89
A10: TMT_10mm | B10: 35.16 | C10: 71 | D10: 71 | F10: 65.23 | G10: 71 | I10: 355 | J10: 355 | L10: 6470 | M10: 55 | O10: January | P10: 615458 | Q10: 90822 | S10: January | T10: 615458 | U10: 90822 | W10: JSW | X10: Kg | Y10: Discrete | Z10: 6.21 | AA10: 15.65 | AB10: 1 | AC10: 100 | AD10: 73 | AE10: 3.88
A11: TMT_12mm | B11: 42.4 | C11: 52 | D11: 51 | F11: 77.58 | G11: 50 | I11: 561 | J11: 561 | L11: 7801 | M11: 75 | O11: TOTAL | P11: 2640294 | Q11: 372284 | S11: TOTAL | T11: 2640294 | U11: 372284 | W11: Concreto | X11: Kg | Y11: Discrete | Z11: 1.84 | AA11: 7.15 | AB11: 2 | AC11: 50 | AD11: 19 | AE11: 4.57
A12: Stirrup_Square | B12: 28.48 | C12: 100 | D12: 50 | F12: 60.12 | G12: 15 | I12: 300 | J12: 300 | L12: 5240 | M12: 52
A13: Stirrup_Circular | B13: 36.03 | C13: 87.5 | D13: 25 | F13: 75.04 | G13: 10 | I13: 400 | J13: 400 | L13: 6629 | M13: 62
A14: Stirrup_Rect | B14: 49.55 | C14: 100 | D14: 200 | F14: 84.13 | G14: 10 | I14: 450 | J14: 450 | L14: 9117 | M14: 73 | O14: Month | P14: Nuvoco | Q14: JSW | R14: Ultratech | S14: Concreto | T14: TOTAL
A15: Paint | B15: 3.39 | C15: 10 | D15: 5 | F15: 6.44 | G15: 2 | I15: 30 | J15: 30 | L15: 624 | M15: 59 | O15: August | P15: 187 | Q15: 104 | R15: 130 | S15: 34 | T15: =SUM(P15:S15) -> 455
A16: Primer | B16: 3.07 | C16: 6 | D16: 10 | F16: 5.08 | G16: 1 | I16: 30 | J16: 30 | L16: 564 | M16: 73 | O16: September | P16: 105 | Q16: 193 | R16: 63 | S16: 56 | T16: =SUM(P16:S16) -> 417
A17: Binding_Wire | B17: 0.73 | C17: 10 | D17: 10 | F17: 2.64 | G17: 5 | I17: 20 | J17: 20 | L17: 135 | M17: 16 | O17: October | P17: 82 | Q17: 227 | R17: 86 | S17: 77 | T17: =SUM(P17:S17) -> 472
A18: Tarpaulin_Cover | B18: 0.26 | C18: 4 | D18: 2 | F18: 1.07 | G18: 2 | I18: 8 | J18: 8 | L18: 47 | M18: 12 | O18: November | P18: 289 | Q18: 127 | R18: 275 | S18: 33 | T18: =SUM(P18:S18) -> 724
O19: December | P19: 131 | Q19: 119 | R19: 185 | S19: 38 | T19: =SUM(P19:S19) -> 473
O20: January | P20: 337 | Q20: 372 | R20: 332 | S20: 100 | T20: =SUM(P20:S20) -> 1141
O21: TOTAL | P21: =SUM(Calculations!$P$15:$P$20) -> 1131 | Q21: =SUM(Calculations!$Q$15:$Q$20) -> 1142 | R21: =SUM(Calculations!$R$15:$R$20) -> 1071 | S21: =SUM(Calculations!$S$15:$S$20) -> 338 | T21: =SUM(Calculations!$T$15:$T$20) -> 3682
A23: Product | B23: Mean | C23: SD | D23: Lead Time | F23: Safety Stock | G23: Reorder Point | J23: Product | L23: Average CP | M23: Average SP | N23: Profit | O23: Avg profit margin
A24: Nuvoco | B24: 6.15 | C24: 15.41 | D24: 5 | F24: 25.4265 | G24: 56.1765 | J24: UltraTech | L24: 268.27 | M24: 332.93 | N24: 67490 | O24: 19.38
A25: UltraTech | B25: 5.82 | C25: 15.55 | D25: 5 | F25: 25.6575 | G25: 54.7575 | J25: JSW | L25: 270 | M25: 320 | N25: 57100 | O25: 15.62
A26: JSW | B26: 6.21 | C26: 15.65 | D26: 5 | F26: 25.8225 | G26: 56.8725 | J26: Nuvoco | L26: 292.83 | M26: 353.51 | N26: 69545 | O26: 17.16
A27: Concreto | B27: 1.84 | C27: 7.15 | D27: 5 | F27: 11.7975 | G27: 20.9975 | J27: Concreto | L27: 360 | M27: 414.5 | N27: 18280 | O27: 13.13
A28: TMT 8mm | B28: 3 | C28: 13.26 | D28: 5 | F28: 21.879 | G28: 36.879
A29: TMT 10mm | B29: 35.16 | C29: 65.23 | D29: 5 | F29: 107.6295 | G29: 283.4295 | J29: Product | L29: Average CP | M29: Average SP | N29: Profit | O29: Avg profit margin
A30: TMT 12 mm | B30: 42.4 | C30: 77.58 | D30: 5 | F30: 128.007 | G30: 340.007 | J30: 8mm | L30: 55 | M30: 59 | N30: 2208 | O30: 6.78
A31: Stirrup Square | B31: 28.48 | C31: 60.12 | D31: 5 | F31: 99.198 | G31: 241.598 | J31: 10mm | L31: 51.85 | M31: 55.85 | N31: 20830 | O31: 5.86
A32: Stirrup Circle | B32: 36.03 | C32: 75.04 | D32: 5 | F32: 123.816 | G32: 303.966 | J32: 12mm | L32: 52 | M32: 55 | N32: 23403 | O32: 5.45
A33: Stirrup Rectangle | B33: 49.55 | C33: 84.13 | D33: 5 | F33: 138.8145 | G33: 386.5645
J34: Product | L34: Average CP | M34: Average SP | N34: Profit | O34: Avg profit margin
J35: Square | L35: 8 | M35: 12 | N35: 20960 | O35: 33.33
J36: Rectangle | L36: 8 | M36: 12 | N36: 36968 | O36: 33.33
J37: Circle | L37: 8.38 | M37: 9.24 | N37: 5795 | O37: 9.08
A47: ROUGH WORK
A50: Sales day (for calculating box plot)
A51: Nuvoco | B51: UltraTech | C51: JSW | D51: Concreto | F51: TMT_8mm | G51: TMT_10mm | I51: TMT_12mm | J51: Stirrup_Square | L51: Stirrup_Rect | M51: Stirrup_Circular | N51: Primers | O51: Paints
A52: 20 | B52: 10 | C52: 5 | D52: 4 | F52: 46 | G52: 71 | I52: 102 | J52: 100 | L52: 160 | M52: 150 | N52: 5 | O52: 2
A53: 10 | B53: 50 | C53: 10 | D53: 30 | F53: 46 | G53: 142 | I53: 51 | J53: 100 | L53: 160 | M53: 125 | N53: 10 | O53: 5
A54: 30 | B54: 15 | C54: 10 | D54: 20 | F54: 46 | G54: 142 | I54: 51 | J54: 100 | L54: 60 | M54: 25 | N54: 2 | O54: 5
A55: 100 | B55: 10 | C55: 5 | D55: 12 | F55: 46 | G55: 71 | I55: 102 | J55: 50 | L55: 100 | M55: 30 | N55: 2 | O55: 4
...

Sheet Visuals
A1: Month | B1: Revenue | C1: Profit
A2: August | B2: 337786 | C2: 49794 | L2: Month | M2: Cement | N2: TMT Bars | O2: Stirrups | P2: Others | Q2: Grand Total
A3: September | B3: 372451 | C3: 45863 | L3: Aug 2025 | M3: 156870 | N3: 112436 | O3: 36740 | P3: 30980 | Q3: =SUM(M3:P3) -> 337026
A4: October | B4: 369845 | C4: 50566 | I4: Product | J4: Margin | L4: Sep 2025 | M4: 142890 | N4: 156769 | O4: 27857 | P4: 42955 | Q4: =SUM(M4:P4) -> 370471
A5: November | B5: 518682 | C5: 77245 | I5: UltraTech | J5: 19.38 | L5: Oct 2025 | M5: 161840 | N5: 123659 | O5: 34886 | P5: 49460 | Q5: =SUM(M5:P5) -> 369845
A6: December | B6: 426072 | C6: 57994 | I6: JSW | J6: 15.62 | L6: Nov 2025 | M6: 245900 | N6: 136009 | O6: 52473 | P6: 84680 | Q6: =SUM(M6:P6) -> 519062
A7: January | B7: 615458 | C7: 90822 | I7: Nuvoco | J7: 17.16 | L7: Dec 2025 | M7: 163440 | N7: 144212 | O7: 41120 | P7: 77300 | Q7: =SUM(M7:P7) -> 426072
A8: TOTAL | B8: 2640294 | C8: 372284 | I8: Concreto | J8: 13.13 | L8: Jan 2026 | M8: 220395 | N8: 89358 | O8: 22520 | P8: 24020 | Q8: =SUM(M8:P8) -> 356293
I9: 8mm bar | J9: 6.78 | L9: TOTAL | M9: =SUM(M3:M8) -> 1091335 | N9: =SUM(N3:N8) -> 762443 | O9: =SUM(O3:O8) -> 215596 | P9: =SUM(P3:P8) -> 309395 | Q9: =SUM(Q3:Q8) -> 2378769
I10: 10mm bar | J10: 5.86
I11: 12mm bar | J11: 5.45
I12: Stirrup Square | J12: 33.33
I13: Stirrup Rect | J13: 33.33
I14: Stirrup Circle | J14: 9.08
I15: Paint | J15: 14.29
I16: Primer | J16: 18.18
I17: Cover | J17: 10
I18: Binding Wire | J18: 7.81
B39: Column | C39: Data Type | D39: Purpose in Analysis
B40: Date | C40: Temporal | D40: Enables Time Based Analysis for Demand Trends
B41: Product | C41: Categorical | D41: Uniquely identifies each product
B42: Category | C42: Categorical | D42: For Categorical Comparison
B43: Quantity | C43: Numerical | D43: Used in Demand and ROP Analysis
B44: Unit | C44: Categorical | D44: Measurement Unit for Each Product Type
B45: Cost Price | C45: Numerical | D45: Profit Margin Computation
B46: Selling Price | C46: Numerical | D46: Profit Margin Computation
B47: Revenue | C47: Numerical | D47: Measurement for Revenue generated by Shop
B48: Profit | C48: Numerical | D48: Transaction Level Profit ; Used in Profit Margin Analysis
